Workbook

Sheet README
A1: Nyaymalaw - Build Plan
A2: Generated 2026-08-27 from docs/PRD.md and docs/ARCHITECTURE.md
A5: What this is | B5: The full build to an enterprise-grade NM. Sheets: Backlog (the work), Epics (grouping and order), Dependencies (what blocks what), PRD Coverage (every decision mapped to the story or audit item that discharges it), Bugs (defect record), Spikes (timeboxed unknowns), Baseline (the measurement record), Advocate Behaviour (the 28-tenet implementation audit and improvement plan), Summary (roll-ups).
A6: Team assumption | B6: Solo. One sequential track; dependencies are hard, not advisory.
A8: Definition of done | B8: From PRD E7 and E8, not a generic one. A story is done when its invariant test EXISTS AND HAS RUN, and - for anything on a served path - when it has been verified live in the browser and the answer read. A test that has never run does not count as a test.
A9: Status vocabulary | B9: decided -> built -> tested -> verified live. Nothing is reported above 'built' without naming the test that supports it and when it last ran.
A11: Estimation - read this | B11: Points are Fibonacci (1,2,3,5,8,13). Anything at 13 is a candidate to split or turn into a spike. Points alone will mislead on this project and there is direct evidence: on the s.49 gap, three confident diagnoses in a row were wrong and each was excluded only by instrumenting stage by stage. An '8-point retrieval fix' was really a 1 or a 40 depending on where the cause actually sat.
A12: Uncertainty class | B12: Known - size is a real estimate. Needs measurement - size is a guess until a measurement lands. Unknown until instrumented - do NOT trust the number; run the spike first. Phase 4 onward is estimated on foundations that are not yet measured, so treat those points as provisional by default.
A13: Ordering key | B13: Order is driven by 'What it unlocks', not by effort. The manifest is early because until it exists every later retrieval measurement is uninterpretable. Verification is early because it is the only structure that turns grounding from a prompt instruction into a property of the data path.
A15: Not in this plan | B15: Sprint dates and velocity. There is no throughput data yet, and fake sprint boundaries would be theatre. Milestones are ordered; cadence is yours to set once real throughput exists.
A16: Test classes | B16: A = pure logic, no corpus, no LLM, every commit. B = structural, asserted at runtime on every real turn. C = corpus, on every ingest or index change. D = judgement, rubric and a judge model, approved runs only.
A17: Standing constraint | B17: Golden and end-to-end evaluations are never run without explicit per-run approval, including targeted re-runs.

Sheet Backlog
A1: ID | B1: Phase | C1: Epic | D1: Story | E1: Type | F1: PRD rules | G1: Arch | H1: Pts | I1: Uncertainty | J1: Depends on | K1: What it unlocks | L1: Acceptance - the test | M1: Test class | N1: Status | O1: What was built | P1: Evidence | Q1: Completed
A2: F-01 | B2: Phase 0 - Foundation | C2: EP-01 | D2: Split the repo into core / ports / adapters / knowledge / edge / obs | E2: Infra | F2: P1 | G2: 9.1 | H2: 3 | I2: Known | K2: Every later story can state which layer it belongs to | L2: Directory structure exists; every module has a declared layer | M2: A | N2: tested | O2: nm/ layer tree: core, ports, adapters, knowledge, edge, obs, tools, with tests split by PRD test class. Legacy tree left in place and runnable, deliberately. | P2: nm/tests/a_logic/test_layering.py (ran 2026-08-27) | Q2: 2026-08-27
A3: F-02 | B3: Phase 0 - Foundation | C3: EP-01 | D3: CI rule: core may import only core and ports; violation fails the build | E3: Infra | F3: P1 | G3: 9.1 | H3: 2 | I3: Known | J3: F-01 | K3: Class-A cadence becomes durable rather than aspirational | L3: A commit adding an adapter import to core/ fails CI | M3: A | N3: tested | O3: nm/tools/layercheck.py: AST check of layer rules AND the legacy boundary, in every layer. core/ports/obs proved stdlib-only. Wired into CI as a build failure, not a warning. | P3: nm/tests/a_logic/test_layering.py (ran 2026-08-27) | Q3: 2026-08-27
A4: F-03 | B4: Phase 0 - Foundation | C4: EP-01 | D4: Class-A test runner: no corpus, no LLM, whole suite under 10s | E4: Eval | F4: E1,E2 | G4: 9.2 | H4: 3 | I4: Known | J4: F-01 | K4: Every pure-logic PRD rule becomes enforceable at commit time | L4: Suite runs on every commit and completes under 10s with no network | M4: A | N4: tested | O4: Class-A suite enforces its own preconditions: sockets disabled for the session, legacy imports raise, 10s budget fails the run. 76 tests currently at 0.21s. | P4: nm/tests/a_logic/test_class_a_guarantees.py (ran 2026-08-27) | Q4: 2026-08-27
A5: F-04 | B5: Phase 0 - Foundation | C5: EP-01 | D5: Class-B runtime assertion framework writing to TurnMetrics.violations | E5: Eval | F5: E3 | G5: 10.2 | H5: 5 | I5: Known | J5: F-01,D-01 | K5: Every real turn becomes a test at no extra cost | L5: An asserted invariant failure appears in TurnMetrics and does not block the answer | M5: A | N5: tested | O5: nm/obs/invariants.py: require() records and ships, require_grounded() blocks. The rule's FAMILY decides policy, not the call site. Rule registry makes violations self-describing; an unregistered id logs at ERROR and records against OBS-1 without blocking. | P5: nm/tests/a_logic/test_obs.py (ran 2026-08-27) | Q5: 2026-08-27
A6: F-05 | B6: Phase 0 - Foundation | C6: EP-01 | D6: Class-C corpus test runner | E6: Eval | F6: E1 | G6: 9.2 | H6: 3 | I6: Known | J6: F-01 | K6: Corpus and retrieval quality become repeatable measurements | L6: Runner executes against a corpus snapshot and reports pass/fail per check | M6: A | N6: tested | O6: Class-C conftest: corpus fixture requiring a VERSION stamp (G21). A missing corpus SKIPS rather than fails, and the skip is reported - green with everything skipped must not read as green with everything passing. | P6: nm/tests/c_corpus/test_corpus_identity.py (ran 2026-08-27) | Q6: 2026-08-27
A7: F-06 | B7: Phase 0 - Foundation | C7: EP-01 | D7: Class-D rubric harness using a judge model distinct from the answering model | E7: Eval | F7: E4 | G7: 11 | H7: 5 | I7: Needs measurement | J7: F-05 | K7: Judgement-grade rules can be measured without correlated blind spots | L7: Judge model is configurably different; rubric cases are drawn from sampled real sessions | M7: D | N7: tested | O7: nm/obs/judgement.py: judge model must differ from the answering model (E4); case-set provenance required and authored sets refused (C5D); runs are proposed with a stated cost and authorise() refuses without an approval naming THIS run (E5). | P7: nm/tests/a_logic/test_foundation.py (ran 2026-08-27) | Q7: 2026-08-27
A8: F-07 | B8: Phase 0 - Foundation | C8: EP-01 | D8: Baseline record, seeded with the measurements already taken | E8: Eval | F8: E6 | G8: 10 | H8: 2 | I8: Known | J8: F-08 | K8: 'Did this get worse' becomes answerable | L8: File holds current value, date and method for every measured quantity | M8: A | N8: tested | O8: nm/obs/baseline.py + baseline.json: 16 measured quantities with per-quantity direction, so verdicts follow intent not arithmetic. Informational quantities never read as improved or regressed. move() requires a non-blank reason (E6). | P8: nm/tests/a_logic/test_obs.py (ran 2026-08-27) | Q8: 2026-08-27
A9: F-08 | B9: Phase 0 - Foundation | C9: EP-01 | D9: Turn metrics: latency, call count, tokens, model mix, per-stage timings | E9: Infra | F9: D2B,E6 | G9: 7.13 | H9: 3 | I9: Known | J9: F-01 | K9: Cost regressions become detectable; D2B becomes enforceable | L9: Every turn writes a complete TurnMetrics row | M9: A | N9: tested | O9: nm/obs/metrics.py: TurnMetrics + TurnRecorder behind a ContextVar. Stage timings accumulate rather than overwrite; metrics recorded even when the turn raises; a failing sink never fails the turn. Replaces log-line timings that nothing collected. | P9: nm/tests/a_logic/test_obs.py (ran 2026-08-27) | Q9: 2026-08-27
A10: F-09 | B10: Phase 0 - Foundation | C10: EP-01 | D10: Status tracking: decided / built / tested / verified live | E10: Infra | F10: E7,E8 | G10: 12 | H10: 2 | I10: Known | J10: F-03 | K10: Progress claims become falsifiable | L10: Each PRD decision carries a status and the test that supports it | M10: A | N10: tested | O10: nm/core/status.py: the E7 ladder as an ordered enum. Anything above `built` requires the test AND when it last ran, enforced at construction. highest_claimable() is conservative - offline green is `tested`, never `verified live`. | P10: nm/tests/a_logic/test_foundation.py (ran 2026-08-27) | Q10: 2026-08-27
A11: F-10 | B11: Phase 0 - Foundation | C11: EP-01 | D11: Error policy: programming errors caught separately and logged at ERROR with traceback | E11: Infra | F11: P5 | G11: 10.3 | H11: 3 | I11: Known | J11: F-01 | K11: A NameError stops looking like a model failure | L11: A deliberate NameError in a handler surfaces at ERROR with a traceback, not a warning | M11: A | N11: tested | O11: nm/core/errors.guard() names expected failures and lets programming errors through with a traceback. nm/tools/exceptcheck.py makes it a build step (guard / re-raise / fail-open reason). Found a real violation in metrics.py on first run. | P11: nm/tests/a_logic/test_foundation.py (ran 2026-08-27) | Q11: 2026-08-27
A12: F-11 | B12: Phase 0 - Foundation | C12: EP-01 | D12: Prompt ownership registry: exactly one owner per step, no duplicated text | E12: Infra | F12: - | G12: 10.5 | H12: 3 | I12: Known | J12: F-01 | K12: A prompt change lands everywhere it should, by construction | L12: No prompt string appears in two modules; a change to a step's prompt has one site | M12: A | N12: tested | O12: nm/core/steps.py: one owner per prompt. Duplicate prompt text is refused, with a whitespace-normalised fingerprint because reformatting is how the second owner appears. | P12: nm/tests/a_logic/test_foundation.py (ran 2026-08-27) | Q12: 2026-08-27
A13: F-12 | B13: Phase 0 - Foundation | C13: EP-01 | D13: Per-step model policy declaration; cheap model is the default | E13: Infra | F13: D2B | G13: 10.6 | H13: 2 | I13: Known | J13: F-08 | K13: model_mix becomes derivable without scattered instrumentation | L13: Every LLM-calling step declares its model and the reason if it is not the cheap one | M13: A | N13: tested | O13: nm/core/steps.py: cheap model is the default; strong requires a justification naming the measurement. strong_model_report() is what a cost review reads (D2B). | P13: nm/tests/a_logic/test_foundation.py (ran 2026-08-27) | Q13: 2026-08-27
A14: D-01 | B14: Phase 0 - Foundation | C14: EP-02 | D14: Core entity definitions from the information view | E14: Core | F14: - | G14: 7 | H14: 8 | I14: Known | J14: F-01 | K14: Every rule gets somewhere to live | L14: All entities in ARCHITECTURE 7 exist as types with non-optional fields as specified | M14: A | N14: tested | O14: re-affirmed after review fixes | P14: nm/tests/a_logic/test_entities.py (ran 2026-08-27) | Q14: 2026-08-27
... A40: I-02 | B40: Phase 1 - Knowledge | C40: EP-05 | D40: Judgment ingestion with paragraph classification | E40: Knowledge | F40: C3 | G40: 5 | H40: 8 | I40: Known | J40: K-01 | K40: Attribution to the court becomes possible | L40: Every paragraph carries a kind; unclassified is explicit, not absent | M40: C | N40: tested | O40: nm/knowledge/judgments.py::_ascending_run (B-63). A marker's span is evidence about its own paragraph and nothing more. Measured, a 2022 Supreme Court judgment offered the markers 1, 2, 3, 366, 4 - the 366 a citation fragment - and 366's span ran 4,251 characters to the next marker while the true paragraph 4 held 576, so the chain 1,2,3,366 outweighed 1,2,3,4 and 60% of the judgment became one 'paragraph 366' carrying one kind and one attribution. That is a C3 problem, not a tidiness one. A document with five markers has no paragraphs 4 to 365, so a number larger than the count of markers cannot be a paragraph index: it is not rejected, it is simply not paid for the text it swallowed, and where two readings then weigh the same the one whose numbering counts its own paragraphs wins. The cap is deliberately narrow - requiring 1, 2, 3 was tried and one hidden marker truncated whole chains (B-62). Measured over 300 judgments: the final paragraph shrank in 37 and grew in 2, releasing 389,262 characters. Residue: judgments with no numbering at all, where one block is an honest reading. | P40: nm/tests/a_logic/test_judgments.py::test_a_number_that_cannot_be_a_paragraph_index_is_not_paid_for_what_it_swallowed, ::test_a_sparsely_numbered_judgment_is_not_truncated_by_the_same_rule (ran 2026-08-28) | Q40: 2026-08-28
A41: I-03 | B41: Phase 1 - Knowledge | C41: EP-05 | D41: Ingest Telangana High Court, 2019 onward | E41: Knowledge | F41: D3A | G41: 5 | H41: 13 | I41: Unknown until instrumented | J41: I-02 | K41: The binding court for the jurisdiction stops being absent | L41: Manifest shows non-zero Telangana HC coverage for 2019 onward | M41: C | N41: decided
A42: I-04 | B42: Phase 1 - Knowledge | C42: EP-05 | D42: Classification pass over unclassified paragraphs | E42: Knowledge | F42: C3 | G42: 5 | H42: 8 | I42: Needs measurement | J42: I-02 | K42: A quarter of the case corpus moves from unusable to attributable | L42: Unknown share is reported after the pass; residue keeps the interim rule | M42: C | N42: built | O42: nm/knowledge/classify.py - the pass's plan and result type. A low-confidence reading stays UNKNOWN, and a residue of zero is treated as a DEFECT signal rather than a win. Cost measured on a spread sample and scaled: ~250,398 unclassified paragraphs, ~114.5M input tokens. Not run - E5 requires approval. | P42: nm/tests/a_logic/test_classify.py (8 class-A rules) (ran 2026-08-27) | Q42: 2026-08-27
A43: I-05 | B43: Phase 1 - Knowledge | C43: EP-05 | D43: Era metadata: commencement and repeal dates on ingest | E43: Knowledge | F43: D3B,G1 | G43: 5 | H43: 5 | I43: Known | J43: K-02 | K43: Point-in-time resolution gets its inputs | L43: Every ingested provision carries commencement and, where applicable, repeal | M43: C | N43: tested | O43: nm/knowledge/sources.py - an Act is named by what it STATES, not by what it is filed as (B-60, B-42). A filename is a lossy rendering of a title: the filesystem cannot hold a slash, so `Municipal Councils/Nagar Panchayats` is filed as `CouncilsNagar` and keys to a different subject. Measured, 60 of 1,655 raw files carry a filename naming a different Act than the document does - sixty times what the defect recorded - and one of them took its name from a definition clause forty lines into the text. The title is read STRUCTURALLY, as the line above the instrument-number line where both scrape templates put it, rather than by pattern: the worst-keyed Act ends in a bare year and matches no reasonable title regex, and it is exactly the file whose name came from a definition clause. 1,613 of 1,655 state a title; the remaining 42 keep the filename and say so, so no subject is silently keyed on the weaker source. Zero-width encoding artefacts are stripped wherever a raw value is read: a byte-order mark is invisible, so two titles differing only by one look identical and compare unequal. | P43: nm/tests/a_logic/test_sources_title.py (6 tests); nm/tests/c_corpus/test_source_titles.py::test_the_act_named_from_a_definition_clause_is_keyed_on_its_real_title (ran 2026-08-28) | Q43: 2026-08-28
A44: I-06 | B44: Phase 1 - Knowledge | C44: EP-05 | D44: Idempotent ingest with deduplication | E44: Knowledge | F44: - | G44: 5 | H44: 5 | I44: Known | J44: I-01 | K44: Re-ingestion stops silently duplicating the corpus | L44: Re-running ingestion over the same source changes nothing | M44: C | N44: tested | O44: Ingestion is a pure fold over a sorted input, so re-running cannot duplicate: verified identical across two runs. Deduplication resolves 16,956 ids claimed by more than one provision - a section printing a second lettered list, and two files keying to one subject - by keeping the fuller text, which is the union-preserving choice measured in subject.py. Every discarded copy is reported. | P44: test_ingest_corpus.py::test_re_running_ingestion_over_the_same_source_changes_nothing (ran 2026-08-27) | Q44: 2026-08-27
A45: I-07 | B45: Phase 1 - Knowledge | C45: EP-05 | D45: Artefact identity stamping on every derived store | E45: Knowledge | F45: G21 | G45: 10.4 | H45: 3 | I45: Known | J45: I-06 | K45: Staleness becomes detectable across all derived artefacts | L45: Every index, store and summary records what it was built from | M45: C | N45: tested | O45: nm/knowledge/artefact.py - one owner for G21. An artefact cannot be constructed without naming its inputs, and the builder is part of the identity so a store rebuilt by a changed prompt is a different artefact even when every input byte matches. Generalises the rule that previously existed separately on the graph and the manifest. | P45: nm/tests/a_logic/test_artefact.py (9 class-A rules) (ran 2026-08-27) | Q45: 2026-08-27
A46: I-08 | B46: Phase 1 - Knowledge | C46: EP-05 | D46: Stale-artefact refusal | E46: Knowledge | F46: G21 | G46: 10.4 | H46: 3 | I46: Known | J46: I-07 | K46: A stale index stops serving old results silently | L46: An artefact older than its source is refused, not used | M46: C | N46: tested | O46: Identity.require_current refuses rather than warns, and the refusal names what changed, what vanished and what is present but was not built from. Bounded so an artefact is judged only against the inputs it declared - an index over the Acts is not refused because the case store moved. | P46: nm/tests/a_logic/test_artefact.py::test_an_artefact_whose_source_changed_is_refused_not_warned_about and peers (ran 2026-08-27) | Q46: 2026-08-27
A47: I-09 | B47: Phase 1 - Knowledge | C47: EP-05 | D47: Close the thinly-ingested Acts, intended subjects first | E47: Knowledge | F47: D5A,M4,D4 | G47: 10.4 | H47: 13 | I47: Needs measurement | J47: I-01,M-03 | K47: Coverage claims become true at section granularity, so a refusal is honest and a gap is nameable | L47: No manifest subject reports sections absent below the highest it holds; the residue is disclosed with a reason per Act rather than counted | M47: C | N47: tested | O47: nm/knowledge/gaps.py - per-Act disclosure joining numbering holes to the refusal records ingestion writes, so a hole carries the reason it exists instead of being counted. Over 1,641 Acts: 1,479 contiguous, 162 with something absent, 205 holes carrying a reason and 144 honest residue. Intended manifest subjects lead the backlog whatever their hole counts. | P47: nm/tests/a_logic/test_gaps.py (7 class-A rules) (ran 2026-08-27) | Q47: 2026-08-27
A48: I-10 | B48: Phase 1 - Knowledge | C48: EP-05 | D48: Section identifiers parsed as identifiers, not as any number on the line | E48: Knowledge | F48: D5A,G1 | G48: 7 | H48: 5 | I48: Known | J48: I-01 | K48: A provision id addresses the provision; numbering integrity becomes a usable coverage signal instead of noise | L48: No Act has a numbering gap wider than the count of sections it holds; a number that cannot be parsed as an identifier fails ingestion rather than being stored | M48: C | N48: tested | O48: Section identifiers are parsed as identifiers: a candidate opening a gap out of scale with the numbering the Act itself holds is refused with its reason and locator, never stored. Acts carrying an out-of-scale gap fell from 312 to 23, and the residue is Acts holding fewer than three identifiers, where no outlier test has a spread to work with. 174 identifiers refused across the tree. | P48: test_ingest.py::test_an_identifier_the_acts_own_numbering_cannot_hold_is_refused; test_ingest_corpus.py::test_no_act_holds_a_numbering_gap_wider_than_its_own_section_count (ran 2026-08-27) | Q48: 2026-08-27
A49: X-01 | B49: Phase 1 - Knowledge | C49: EP-06 | D49: Lexical index build | E49: Knowledge | F49: G3 | G49: 5 | H49: 5 | I49: Known | J49: I-01 | K49: Exact matching on section numbers and defined terms | L49: Index built, versioned and reconciled against source counts | M49: C | N49: tested | O49: nm/knowledge/index.py - BM25 over 291,359 provisions, 48,110 terms, built in 8s and reconciled against its source count. An unseen term contributes nothing rather than a penalty. Article 59 now ranks FIRST for 'cancel or set aside an instrument' - the provision measured at rank 53 of 60 in the original defect. | P49: nm/tests/a_logic/test_index.py (9 class-A rules) (ran 2026-08-27) | Q49: 2026-08-27
A50: X-02 | B50: Phase 1 - Knowledge | C50: EP-06 | D50: Dense index build | E50: Knowledge | F50: G3 | G50: 5 | H50: 5 | I50: Known | J50: I-01 | K50: Paraphrase matching | L50: Index built, versioned and reconciled | M50: C | N50: tested | O50: nm/knowledge/embed.py - dense index built on GPU: 284,447 provisions embedded with all-MiniLM-L6-v2 in 509s, 384 dimensions, stamped with an Identity whose builder carries the model so a store built by a different checkpoint is refused rather than blended. Skips 995 provisions with no text and 5,917 too short to carry meaning. hybrid() fuses lexical and dense on RANK (RRF), not on score - measured, BM25 runs 20-34 and cosine 0-1, so adding them let the lexical leg swamp the dense one entirely. Fusion decides order and never membership: the lexical tail is appended below the fused head. | P50: nm/tests/a_logic/test_index.py (12 class-A rules incl. dense counting, encoder refusal, fusion membership) (ran 2026-08-27) | Q50: 2026-08-27
A51: X-03 | B51: Phase 1 - Knowledge | C51: EP-06 | D51: Section-level summaries | E51: Knowledge | F51: G20 | G51: 5 | H51: 8 | I51: Known | J51: I-01 | K51: The missing middle granularity | L51: Every section has a summary carrying its source identity | M51: C | N51: built | O51: nm/knowledge/summaries.py - Summary type carrying its source digest, section-level per G20. Cost measured and proposed, not initiated: 67,315 sections, ~17.2M input tokens on the cheap model. No summaries generated - E5 requires a bulk run to be approved. | P51: nm/tests/a_logic/test_summaries.py (11 class-A rules) (ran 2026-08-27) | Q51: 2026-08-27
A52: X-04 | B52: Phase 1 - Knowledge | C52: EP-06 | D52: Holding summaries: what a judgment decided, on what facts | E52: Knowledge | F52: G19 | G52: 5 | H52: 13 | I52: Unknown until instrumented | J52: I-02 | K52: On-point-ness gets a representation, so weight stops winning by default | L52: Every judgment has a holding summary distinct from its subject summary | M52: C | N52: built | O52: Holding summaries are a separate TYPE from subject summaries so one cannot stand for the other - a system holding only subject summaries has no representation of on-point-ness and citation weight wins by default. Cost measured on a spread sample and scaled: ~30,236 judgments, ~210M input tokens. Not run. | P52: nm/tests/a_logic/test_summaries.py::test_the_two_kinds_are_separate_types_so_one_cannot_stand_for_the_other (ran 2026-08-27) | Q52: 2026-08-27
A53: X-05 | B53: Phase 1 - Knowledge | C53: EP-06 | D53: Summary provenance and staleness refusal | E53: Knowledge | F53: G21 | G53: 10.4 | H53: 3 | I53: Known | J53: X-03,I-08 | K53: A fluent stale summary stops being invisible | L53: A summary whose source changed is refused until regenerated | M53: C | N53: tested | O53: A summary carries the digest of the exact provision text it was written from and is refused when that text changes - finer than store-level identity, because a summary goes stale one provision at a time. Staleness is reported per summary so one amended section costs one summary rather than the store. | P53: nm/tests/a_logic/test_summaries.py::test_a_summary_whose_source_changed_is_refused and peers (ran 2026-08-27) | Q53: 2026-08-27
... A171: AN-09 | B171: Phase 4 - Delivery | C171: EP-22 | D171: Summary as single source; board and answer derive | E171: Core | F171: CS1 | G171: 7.15 | H171: 3 | I171: Known | J171: AN-07,AN-08 | K171: Board and answer stop being able to disagree | L171: Neither holds anything the summary does not | M171: B | N171: tested | O171: nm/edge/board.py::Board.of + nm/edge/phase4.py::assert_answer_derives_from_summary - the board is derived by construction (its only filling constructor reads a CaseSummary), and the answer's refs are checked against the summary's known_refs. | P171: nm/tests/a_logic/test_phase4_answer.py::test_the_board_can_hold_nothing_the_summary_does_not, ::test_an_answer_citing_what_the_summary_does_not_hold_is_reported (ran 2026-08-28) | Q171: 2026-08-28
A172: AN-10 | B172: Phase 4 - Delivery | C172: EP-22 | D172: Summary reads as a case note, not a debug dump | E172: Edge | F172: CS5 | G172: 7.15 | H172: 3 | I172: Known | J172: AN-08 | K172: The advocate can take it into a conference | L172: No identifiers, scores or pipeline state | M172: D | N172: built | O172: nm/core/summary.py::render_case_note, identifier_leaks - the MECHANICAL half of CS5 is tested: no internal identifier reaches the case note, checked exactly against internal_ids because the ids are known. DOWNGRADED from tested after review. AN-10 is a Class D story and its acceptance ('reads as a case note, not a debug dump') is a judgement criterion that has not run - E5 requires per-run approval and E8 says a test that never ran is not a test. This now matches the Phase 3 precedent, where 13 Class D stories stayed BUILT for exactly this reason. | Q172: 2026-08-28
A173: AN-11 | B173: Phase 4 - Delivery | C173: EP-22 | D173: Inference labelling distinct from citation | E173: Core | F173: D5 | G173: 7.15 | H173: 5 | I173: Known | J173: V-01,AN-01 | K173: Reasoning becomes auditable without being forbidden | L173: Every inference marked; no inference carries a citation as though a proposition | M173: B | N173: tested | O173: nm/core/answer.py::Element + nm/core/assembly.py::render_element - an inference carries PREMISES and structurally cannot carry refs, cannot be a GROUND, and cannot exist unmarked. D5's most dangerous output - an inference dressed as a citation - is made unrepresentable rather than forbidden. | P173: nm/tests/a_logic/test_phase4_answer.py::test_an_inference_cannot_carry_a_citation_as_though_it_were_a_proposition, ::test_an_inference_cannot_be_a_ground, ::test_premises_without_the_label_are_refused (ran 2026-08-28) | Q173: 2026-08-28
A174: DF-01 | B174: Phase 5 - Drafting | C174: EP-23 | D174: DrafterBrief contract | E174: Core | F174: DR1 | G174: 6 | H174: 5 | I174: Known | J174: AN-08 | K174: Re-extraction, where facts get invented, becomes unnecessary | L174: Structured fields, not prose | M174: A | N174: tested | O174: nm/core/brief.py::DrafterBrief - DR1's field list as a typed contract, no free-text field carrying facts, undated facts kept out of the chronology rather than given a position (L3). Unchanged by the review. | P174: nm/tests/a_logic/test_phase5_drafting.py::test_every_fact_crossing_the_boundary_carries_its_provenance, ::test_the_brief_has_no_free_text_field_that_could_carry_a_fact (ran 2026-08-28) | Q174: 2026-08-28
A175: DF-02 | B175: Phase 5 - Drafting | C175: EP-23 | D175: Brief assembly from analysis | E175: Core | F175: DR1 | G175: 6 | H175: 8 | I175: Known | J175: DF-01,TH-01,PF-01 | K175: Drafting gets everything it needs and nothing it should not have | L175: All contract fields populated from matter state | M175: B | N175: tested | O175: nm/core/brief.py::assemble_brief - built from the case summary, refused while a blocking gate is open. HARDENED after review, where 'derives from the summary' turned out to be a claim about intent rather than a property of the code: findings were an arbitrary iterable and are now checked against position.known_refs (CS1); unconfirmed facts reached the pleadable set and are now refused by name (D10); and the cause title INVENTED 'the applicant' / 'the respondent' when parties were absent, which is fluent completion arriving before the drafter - ours and theirs are now required arguments, as is confirmation_threshold. | P175: nm/tests/a_logic/test_phase5_drafting.py::test_the_brief_refuses_an_authority_the_summary_does_not_hold, ::test_an_unconfirmed_fact_cannot_be_pleaded, ::test_the_cause_title_parties_cannot_be_invented (ran 2026-08-28) | Q175: 2026-08-28
A176: DF-03 | B176: Phase 5 - Drafting | C176: EP-23 | D176: Drafting agent as a separate process that cannot retrieve | E176: Adapter | F176: DR2 | G176: 6 | H176: 5 | I176: Known | J176: DF-01 | K176: One audit chain is preserved | L176: The drafter has no retrieval capability; missing law is a request back | M176: A | N176: built | O176: nm/drafting/ as a layer with no access to nm.evidence or nm.knowledge (layercheck), a signature with nowhere to put a retriever, a Composition that cannot exceed the brief, and retrieval_in_reach() which inspects the composer's closure and module globals before it runs. DOWNGRADED from tested after review. The story is 'drafting agent as a SEPARATE PROCESS'; what exists is a layer and signature boundary inside one process. The reach check catches mistakes - a captured retrieval client, a retrieval import in the composer's module - and cannot catch intent: a dynamic import inside the call, a C extension, an attribute off a handed object. ADR-8's process split is what would enforce DR2 against intent, and it is not built. | P176: nm/tests/a_logic/test_phase5_drafting.py::test_a_composer_that_can_reach_retrieval_is_refused_before_it_runs, ::test_the_reach_check_does_not_refuse_the_legitimate_supplier (ran 2026-08-28) | Q176: 2026-08-28
A177: DF-04 | B177: Phase 5 - Drafting | C177: EP-23 | D177: Averment traceability to brief facts | E177: Core | F177: DR3 | G177: 6 | H177: 8 | I177: Known | J177: DF-02 | K177: An unsupported averment stops being filable | L177: Every averment traces to a fact with provenance | M177: B | N177: tested | O177: nm/drafting/draft.py::Averment - an averment cannot be constructed resting on nothing, and Draft carries its BRIEF as a field rather than receiving it at check time. That removes the state the legacy verifier reported as a pass: there is no draft for which the tracing check has nothing to check. Formal text is exempt, because forcing a citation onto 'the plaintiff submits as follows' is a rule that makes the output worse. | P177: nm/tests/a_logic/test_phase5_drafting.py::test_an_averment_resting_on_nothing_cannot_be_built, ::test_a_draft_cannot_be_separated_from_its_brief, ::test_an_averment_on_a_fact_the_brief_does_not_hold_is_caught, ::test_formal_text_is_not_required_to_trace (ran 2026-08-28) | Q177: 2026-08-28
A178: DF-05 | B178: Phase 5 - Drafting | C178: EP-23 | D178: Not-to-plead list travels with the brief | E178: Core | F178: DR4 | G178: 6 | H178: 3 | I178: Known | J178: DF-01,SE-01 | K178: The drafter stops helpfully restoring what was deliberately excluded | L178: Excluded facts and their reasons are in the brief | M178: B | N178: tested | O178: nm/core/brief.py::ExcludedFact + nm/drafting/verify.py::_exclusions_respected - the not-to-plead list travels with the brief and every exclusion carries its reason. The legacy tree has no equivalent field anywhere, so DR4 was absent rather than weak. Verification catches an averment that rests on an excluded fact. | P178: nm/tests/a_logic/test_phase5_drafting.py::test_an_exclusion_must_carry_its_reason, ::test_a_draft_that_restores_an_excluded_fact_is_caught, ::test_an_excluded_fact_does_not_reach_the_pleadable_set (ran 2026-08-28) | Q178: 2026-08-28
A179: DF-06 | B179: Phase 5 - Drafting | C179: EP-23 | D179: Draft verified against its brief before it is shown | E179: Core | F179: DR5 | G179: 6 | H179: 8 | I179: Known | J179: DF-04 | K179: Drafting gets its stricter gate | L179: Every averment traced, every citation in force and binding, every date matched | M179: B | N179: tested | O179: nm/drafting/verify.py - nine mechanical checks with a three-state outcome where could-not-run BLOCKS. CORRECTED after review found FOUR confirmed false passes, all one mistake: _discloses asked whether an authority's reference appeared anywhere in the prose, so citing a persuasive authority counted as disclosing that it was persuasive, citing an overruled judgment counted as disclosing the treatment, and naming the limitation Article counted as pleading compliance. A fifth node kind, Disclosure, now names its subject and kind so the question is an exact lookup - the model changed rather than the check getting cleverer. | P179: nm/tests/a_logic/test_phase5_drafting.py::test_a_citation_is_not_a_disclosure_of_what_is_being_cited, ::test_naming_the_article_is_not_pleading_the_compliance_plea, ::test_a_check_that_could_not_run_does_not_clear (ran 2026-08-28) | Q179: 2026-08-28
A180: DF-07 | B180: Phase 5 - Drafting | C180: EP-23 | D180: Gaps marked as blanks, never filled | E180: Core | F180: DR6 | G180: 6 | H180: 5 | I180: Known | J180: DF-02 | K180: The highest-risk drafting failure becomes structurally prevented | L180: A draft with no blanks on a file with open gaps is a defect | M180: B | N180: tested | O180: nm/drafting/draft.py::Blank - a blank is a NODE, not a string convention. The legacy tree asked a model for [GAP: ...] in a prompt and stripped unresolved tags at render time, which is the one operation that turns a visible hole invisible. Blanks are computed from the brief's open gaps and appended by the drafter, so they are not the composer's to tidy; set equality is checked BOTH ways, so a hole cannot be dropped or invented. | P180: nm/tests/a_logic/test_phase5_drafting.py::test_a_draft_with_no_blanks_on_a_file_with_open_gaps_is_a_defect, ::test_a_blank_cannot_be_invented_any_more_than_it_can_be_filled, ::test_the_drafter_supplies_owed_blanks_the_composer_left_out (ran 2026-08-28) | Q180: 2026-08-28
A181: DF-08 | B181: Phase 5 - Drafting | C181: EP-23 | D181: Drafter does not re-decide ranked reliefs or selected arguments | E181: Core | F181: DR7 | G181: 6 | H181: 2 | I181: Known | J181: DF-02 | K181: Judgement stays in the component held to the advising standard | L181: The draft follows the brief's ranking | M181: B | N181: tested | O181: nm/drafting/verify.py::_reliefs_follow_the_brief + agent.py::RankingObjection - the draft's prayers must equal the brief's relief order as a sequence. CORRECTED after review: Prayer accepted empty text, so a prayer that asked the court for nothing satisfied the ranking comparison. | P181: nm/tests/a_logic/test_phase5_drafting.py::test_the_draft_follows_the_briefs_ranking, ::test_a_prayer_must_carry_the_text_that_is_actually_filed (ran 2026-08-28) | Q181: 2026-08-28
A182: EN-01 | B182: Phase 6 - Enterprise | C182: EP-24 | D182: Accounts and advocate identity | E182: Enterprise | F182: - | G182: 5 | H182: 8 | I182: Known | J182: F-01 | K182: Multi-user becomes possible | L182: Sign-in, identity, session lifecycle | M182: B | N182: built | O182: nm/core/identity.py - Advocate, Chambers and Session with the lifecycle COMPUTED rather than stored, so a session cannot report itself active after it expired. Advocate is deliberately thin: no email, no client-identifying field, because the way personal data reaches a diagnostics store is by riding on a value nobody thought of as personal. NOT DONE: sign-in itself - credentials, token issue, reset - which needs an adapter and an edge that do not exist. Identity and lifecycle are tested; the story is not. | Q182: 2026-08-28
...

Sheet Epics
A1: Epic | B1: Phase | C1: Name | D1: Why it is here | E1: Stories | F1: Points | G1: Unknowns
A2: EP-01 | B2: Phase 0 - Foundation | C2: Engineering foundation and the eval harness | D2: The test cadence is a design input; nothing later is enforceable without it | E2: =COUNTIF(Backlog!$C$2:$C$218,$A2) | F2: =SUMIF(Backlog!$C$2:$C$218,$A2,Backlog!$H$2:$H$218) | G2: =COUNTIFS(Backlog!$C$2:$C$218,$A2,Backlog!$I$2:$I$218,"Unknown until instrumented")
A3: EP-02 | B3: Phase 0 - Foundation | C3: Data model and derivation graph | D3: A schema that cannot express a rule makes that rule unimplementable | E3: =COUNTIF(Backlog!$C$2:$C$218,$A3) | F3: =SUMIF(Backlog!$C$2:$C$218,$A3,Backlog!$H$2:$H$218) | G3: =COUNTIFS(Backlog!$C$2:$C$218,$A3,Backlog!$I$2:$I$218,"Unknown until instrumented")
A4: EP-03 | B4: Phase 1 - Knowledge | C4: Legal graph | D4: Resolution needs structure to resolve against | E4: =COUNTIF(Backlog!$C$2:$C$218,$A4) | F4: =SUMIF(Backlog!$C$2:$C$218,$A4,Backlog!$H$2:$H$218) | G4: =COUNTIFS(Backlog!$C$2:$C$218,$A4,Backlog!$I$2:$I$218,"Unknown until instrumented")
A5: EP-04 | B5: Phase 1 - Knowledge | C5: Corpus manifest | D5: Until it exists, an honest refusal and a retrieval defect are indistinguishable | E5: =COUNTIF(Backlog!$C$2:$C$218,$A5) | F5: =SUMIF(Backlog!$C$2:$C$218,$A5,Backlog!$H$2:$H$218) | G5: =COUNTIFS(Backlog!$C$2:$C$218,$A5,Backlog!$I$2:$I$218,"Unknown until instrumented")
A6: EP-05 | B6: Phase 1 - Knowledge | C6: Ingestion | D6: Including the binding court the corpus currently lacks entirely | E6: =COUNTIF(Backlog!$C$2:$C$218,$A6) | F6: =SUMIF(Backlog!$C$2:$C$218,$A6,Backlog!$H$2:$H$218) | G6: =COUNTIFS(Backlog!$C$2:$C$218,$A6,Backlog!$I$2:$I$218,"Unknown until instrumented")
A7: EP-06 | B7: Phase 1 - Knowledge | C7: Indices and summaries | D7: Section level is both the missing retrieval granularity and the missing summary granularity | E7: =COUNTIF(Backlog!$C$2:$C$218,$A7) | F7: =SUMIF(Backlog!$C$2:$C$218,$A7,Backlog!$H$2:$H$218) | G7: =COUNTIFS(Backlog!$C$2:$C$218,$A7,Backlog!$I$2:$I$218,"Unknown until instrumented")
A8: EP-07 | B8: Phase 1 - Knowledge | C8: Citation graph and treatment | D8: Authority lines, and is-this-still-good-law | E8: =COUNTIF(Backlog!$C$2:$C$218,$A8) | F8: =SUMIF(Backlog!$C$2:$C$218,$A8,Backlog!$H$2:$H$218) | G8: =COUNTIFS(Backlog!$C$2:$C$218,$A8,Backlog!$I$2:$I$218,"Unknown until instrumented")
A9: EP-08 | B9: Phase 2 - Evidence | C9: Resolution | D9: The query is the matter, not a sentence | E9: =COUNTIF(Backlog!$C$2:$C$218,$A9) | F9: =SUMIF(Backlog!$C$2:$C$218,$A9,Backlog!$H$2:$H$218) | G9: =COUNTIFS(Backlog!$C$2:$C$218,$A9,Backlog!$I$2:$I$218,"Unknown until instrumented")
A10: EP-09 | B10: Phase 2 - Evidence | C10: Search | D10: Scoped by law; similarity may only reorder | E10: =COUNTIF(Backlog!$C$2:$C$218,$A10) | F10: =SUMIF(Backlog!$C$2:$C$218,$A10,Backlog!$H$2:$H$218) | G10: =COUNTIFS(Backlog!$C$2:$C$218,$A10,Backlog!$I$2:$I$218,"Unknown until instrumented")
A11: EP-10 | B11: Phase 2 - Evidence | C11: Verification | D11: Where grounding stops being an aspiration and becomes a gate | E11: =COUNTIF(Backlog!$C$2:$C$218,$A11) | F11: =SUMIF(Backlog!$C$2:$C$218,$A11,Backlog!$H$2:$H$218) | G11: =COUNTIFS(Backlog!$C$2:$C$218,$A11,Backlog!$I$2:$I$218,"Unknown until instrumented")
A12: EP-11 | B12: Phase 3 - Analysis | C12: Threads and identity | D12: A wrong merge inverts the advice invisibly | E12: =COUNTIF(Backlog!$C$2:$C$218,$A12) | F12: =SUMIF(Backlog!$C$2:$C$218,$A12,Backlog!$H$2:$H$218) | G12: =COUNTIFS(Backlog!$C$2:$C$218,$A12,Backlog!$I$2:$I$218,"Unknown until instrumented")
A13: EP-12 | B13: Phase 3 - Analysis | C13: Facts, provenance and the correction cascade | D13: A corrected fact must not leave stale conclusions beneath it | E13: =COUNTIF(Backlog!$C$2:$C$218,$A13) | F13: =SUMIF(Backlog!$C$2:$C$218,$A13,Backlog!$H$2:$H$218) | G13: =COUNTIFS(Backlog!$C$2:$C$218,$A13,Backlog!$I$2:$I$218,"Unknown until instrumented")
... A32: EP-31 | B32: Phase 7 - Integration | C32: The turn: wiring the components into a product | D32: Every component is tested and nothing has ever run; five P1 defects survived every gate | E32: =COUNTIF(Backlog!$C$2:$C$218,$A32) | F32: =SUMIF(Backlog!$C$2:$C$218,$A32,Backlog!$H$2:$H$218) | G32: =COUNTIFS(Backlog!$C$2:$C$218,$A32,Backlog!$I$2:$I$218,"Unknown until instrumented")

Sheet Dependencies
A1: Story | B1: Blocked by | C1: Story title | D1: Blocker title
A2: F-02 | B2: F-01 | C2: CI rule: core may import only core and ports; violation fails the build | D2: Split the repo into core / ports / adapters / knowledge / edge / obs
A3: F-03 | B3: F-01 | C3: Class-A test runner: no corpus, no LLM, whole suite under 10s | D3: Split the repo into core / ports / adapters / knowledge / edge / obs
A4: F-04 | B4: F-01 | C4: Class-B runtime assertion framework writing to TurnMetrics.violations | D4: Split the repo into core / ports / adapters / knowledge / edge / obs
A5: F-04 | B5: D-01 | C5: Class-B runtime assertion framework writing to TurnMetrics.violations | D5: Core entity definitions from the information view
A6: F-05 | B6: F-01 | C6: Class-C corpus test runner | D6: Split the repo into core / ports / adapters / knowledge / edge / obs
A7: F-06 | B7: F-05 | C7: Class-D rubric harness using a judge model distinct from the answering model | D7: Class-C corpus test runner
A8: F-07 | B8: F-08 | C8: Baseline record, seeded with the measurements already taken | D8: Turn metrics: latency, call count, tokens, model mix, per-stage timings
A9: F-08 | B9: F-01 | C9: Turn metrics: latency, call count, tokens, model mix, per-stage timings | D9: Split the repo into core / ports / adapters / knowledge / edge / obs
A10: F-09 | B10: F-03 | C10: Status tracking: decided / built / tested / verified live | D10: Class-A test runner: no corpus, no LLM, whole suite under 10s
A11: F-10 | B11: F-01 | C11: Error policy: programming errors caught separately and logged at ERROR with traceback | D11: Split the repo into core / ports / adapters / knowledge / edge / obs
A12: F-11 | B12: F-01 | C12: Prompt ownership registry: exactly one owner per step, no duplicated text | D12: Split the repo into core / ports / adapters / knowledge / edge / obs
... A268: EN-29 | B268: EN-19 | C268: Pricing and packaging decision | D268: Per-turn and per-matter cost attribution

Sheet PRD Coverage
A1: # | B1: Date | C1: PRD decision | D1: Section | E1: Discharged by | F1: Status
A2: 1 | B2: 2026-08-26 | C2: Advocate-only product; no direct-to-client mode | D2: D1 | E2: TH-02,AD-04,EN-26 | F2: built
A3: 2 | B3: 2026-08-26 | C3: Corpus stays Telangana + Union of India; gaps disclosed, not filled from memory | D3: D3A | E3: I-03,M-02 | F3: decided
A4: 3 | B4: 2026-08-26 | C4: Launch areas: land & revenue, matrimonial, bail | D4: D4 | E4: M-02 | F4: tested
A5: 4 | B5: 2026-08-26 | C5: Order of work adopted (Part I §1); posture is step 1 | D5: D7 | E5: GQ-01 | F5: tested
A6: 5 | B6: 2026-08-26 | C6: Posture is per matter, not per client; unknown blocks directive advice | D6: D8 | E6: PO-01,PO-02,PO-03,PO-04,PO-05 | F6: tested
A7: 6 | B7: 2026-08-26 | C7: Posture shown as a cause-title table, second element on the matter board | D7: D8 | E7: PO-01,PO-02,PO-03,PO-04,PO-05 | F7: tested
A8: 7 | B8: 2026-08-26 | C8: Left pane default a third of the window, draggable to 40% | D8: D13A | E8: AN-01,AN-02,AN-03,AN-04,AN-05,AN-06,AN-07 | F8: tested
A9: 8 | B9: 2026-08-26 | C9: Enrichment monotonic and evidence-gated; a stated posture is never silently flipped | D9: D8 | E9: PO-01,PO-02,PO-03,PO-04,PO-05 | F9: tested
A10: 9 | B10: 2026-08-26 | C10: No further code changes until a section here is finalised | D10: PROCESS | E10: n/a - working agreement, not a build item | F10: n/a
A11: 10 | B11: 2026-08-26 | C11: NM is senior counsel, not a junior — critical thinker and problem solver; disagrees with the brief, reframes, volunteers, commits to a recommendation, argues the other side, names exposure | D11: D1 | E11: TH-02,AD-04,EN-26 | F11: built
A12: 11 | B12: 2026-08-26 | C12: Expertise is in reasoning and judgement, never in recalling law from memory; the corpus-grounding discipline is unchanged | D12: D5 | E12: V-06,V-07,AN-11,M-04 | F12: tested
A13: 12 | B13: 2026-08-26 | C13: Decisiveness is a requirement — a survey of options is not advice | D13: D2 | E13: AN-02 | F13: tested
... A187: 186 | B187: 2026-08-27 | C187: CS5: the summary reads as a case note, not a debug dump — identifiers, scores and pipeline state belong in diagnostics (G8) | D187: D13A | E187: AN-10 | F187: built
A188: 187 | B188: 2026-08-28 | C188: D16.1: Professional stance - end-to-end advocate behaviour; detailed implementation audit and improvement recommendation are on the Advocate Behaviour sheet. | D188: D16 | E188: AB-01 (Advocate Behaviour sheet) | F188: built
A189: 188 | B189: 2026-08-28 | C189: D16.2: Competence - end-to-end advocate behaviour; detailed implementation audit and improvement recommendation are on the Advocate Behaviour sheet. | D189: D16 | E189: AB-02 (Advocate Behaviour sheet) | F189: built
A190: 189 | B190: 2026-08-28 | C190: D16.3: Before receiving substance - end-to-end advocate behaviour; detailed implementation audit and improvement recommendation are on the Advocate Behaviour sheet. | D190: D16 | E190: AB-03 (Advocate Behaviour sheet) | F190: decided
A191: 190 | B191: 2026-08-28 | C191: D16.4: Authority and engagement - end-to-end advocate behaviour; detailed implementation audit and improvement recommendation are on the Advocate Behaviour sheet. | D191: D16 | E191: AB-04 (Advocate Behaviour sheet) | F191: decided
A192: 191 | B192: 2026-08-28 | C192: D16.5: First human contact - end-to-end advocate behaviour; detailed implementation audit and improvement recommendation are on the Advocate Behaviour sheet. | D192: D16 | E192: AB-05 (Advocate Behaviour sheet) | F192: built
A193: 192 | B193: 2026-08-28 | C193: D16.6: Emergency triage - end-to-end advocate behaviour; detailed implementation audit and improvement recommendation are on the Advocate Behaviour sheet. | D193: D16 | E193: AB-06 (Advocate Behaviour sheet) | F193: built
A194: 193 | B194: 2026-08-28 | C194: D16.7: Client interview - end-to-end advocate behaviour; detailed implementation audit and improvement recommendation are on the Advocate Behaviour sheet. | D194: D16 | E194: AB-07 (Advocate Behaviour sheet) | F194: built
A195: 194 | B195: 2026-08-28 | C195: D16.8: Objectives and constraints - end-to-end advocate behaviour; detailed implementation audit and improvement recommendation are on the Advocate Behaviour sheet. | D195: D16 | E195: AB-08 (Advocate Behaviour sheet) | F195: built
A196: 195 | B196: 2026-08-28 | C196: D16.9: Parties and posture - end-to-end advocate behaviour; detailed implementation audit and improvement recommendation are on the Advocate Behaviour sheet. | D196: D16 | E196: AB-09 (Advocate Behaviour sheet) | F196: tested
A197: 196 | B197: 2026-08-28 | C197: D16.10: Fact model - end-to-end advocate behaviour; detailed implementation audit and improvement recommendation are on the Advocate Behaviour sheet. | D197: D16 | E197: AB-10 (Advocate Behaviour sheet) | F197: tested
A198: 197 | B198: 2026-08-28 | C198: D16.11: Evidence and preservation - end-to-end advocate behaviour; detailed implementation audit and improvement recommendation are on the Advocate Behaviour sheet. | D198: D16 | E198: AB-11 (Advocate Behaviour sheet) | F198: built
A199: 198 | B199: 2026-08-28 | C199: D16.12: Threshold legal map - end-to-end advocate behaviour; detailed implementation audit and improvement recommendation are on the Advocate Behaviour sheet. | D199: D16 | E199: AB-12 (Advocate Behaviour sheet) | F199: built
... A215: 214 | B215: 2026-08-28 | C215: D16.28: After each event and at closure - end-to-end advocate behaviour; detailed implementation audit and improvement recommendation are on the Advocate Behaviour sheet. | D215: D16 | E215: AB-28 (Advocate Behaviour sheet) | F215: built

Sheet Bugs
A1: ID | B1: Found by | C1: Where | D1: Defect | E1: Detail | F1: Sev | G1: Pts | H1: Status | I1: Fix / story | J1: Evidence
A2: B-01 | B2: live session | C2: agents/legal_analysis | D2: Stale call site after a rename emptied every charge map | E2: A rename left `_drop_non_issues` referenced but undefined. It raised NameError on every matter for weeks; a broad `except Exception` logged it as a model failure, so the symptom looked like flakiness. | F2: P1 | G2: 3 | H2: fixed | I2: legacy fix; rule carried into F-10 + exceptcheck | J2: resolve_charges returned 0 charges on a matter with 9 merits issues
A3: B-02 | B3: live session | C3: agents/orchestrator | D3: Every advising turn crashed on an unbound local | E3: The AUTHORITATIVE CHARGES block was indented into the `steps` branch instead of the `charges` branch, so `_cite_how` was used before assignment on every advising turn. | F3: P1 | G3: 2 | H3: fixed | I3: legacy fix; swept by pylint E0601/E0606 in CI | J3: UnboundLocalError on every advising turn; 40/40 offline tests green throughout
A4: B-03 | B4: live session | C4: agents/legal_analysis | D4: An invented track vocabulary emptied the charge map | E4: The charge resolver returned tracks {'civil': 2, 'revenue': 1} — subject words, not procedural tracks. They passed unvalidated and merits_only dropped every one. | F4: P1 | G4: 3 | H4: fixed | I4: legacy fix; generalised as F5 (closed vocabulary validated at every entry) | J4: {'civil','revenue'} -> 0 charges on a 9-issue matter
A5: B-04 | B5: retrieval probe | C5: retrieval/retriever | D5: An unlisted atom type scored below every listed one | E5: `table.get(kind, 0.0)` made any atom type absent from the priors table score worse than all present ones, and the bonus was an absolute constant larger than the whole RRF range (best fused score 2/61). | F5: P1 | G5: 5 | H5: fixed | I5: legacy fix; generalised as R4 (absent key is neutral; scale to the spread) | J5: Limitation Art. 59: rank 1 -> 53 of 60; after the fix rank 1, and rank 2 with its own entry stripped
A6: B-05 | B6: index audit | C6: legal_database | D6: A stale BM25 index served old results silently | E6: The native BM25 index held 411,797 documents against the JSON's 414,710 and had been stale since 11 July, answering every query without complaint. | F6: P1 | G6: 2 | H6: fixed | I6: legacy fix; generalised as G21 / I-08 (stale artefact refused) | J6: 411,797 vs 414,710 documents
A7: B-06 | B7: live session | C7: agents/posture | D7: Posture inverted: advice given to the wrong side | E7: NM told a client who had drawn a dishonoured cheque to file the s.138 complaint against himself, and told an employer who had dismissed a workman that he could claim reinstatement. Every citation was real and apposite. | F7: P1 | G7: 8 | H7: fixed | I7: legacy fix (agents/posture.py); rebuilt as PO-01..PO-05 | J7: 5-dispute live file; 2 of 5 threads inverted. Legacy fix NOT verified live
A8: B-07 | B8: measurement | C8: agents/legal_analysis | D8: Classification deleted 20.1% of every issue ever spotted | E8: The pre-routing filters discarded 641 of 3,192 issue labels across every stored matter, led by limitation (122), bail (86) and forum/jurisdiction (58) — the three an advocate can least afford to lose. | F8: P1 | G8: 5 | H8: fixed | I8: legacy fix (route, never delete); rebuilt as F2 / IS-04 | J8: 641 of 3,192 labels discarded
A9: B-08 | B9: ingest audit | C9: legal_database | D9: A judgment was ingested twice | E9: Vidhyadhar v Manikrao was ingested as a new case while already present under SC_1999_VIDHYADHAR_VS_MANIKRAO_ANR. | F9: P3 | G9: 1 | H9: fixed | I9: removed; prevented by I-06 (idempotent ingest) | J9: 5th false retrieval gap traced to a duplicate
A10: B-09 | B10: live session | C10: agents/orchestrator | D10: A date given in the brief was never applied to limitation | E10: NM was told the debtor acknowledged the debt in writing on 12 June 2024, repeated it back, and still concluded the claim was time-barred counting three years from the March 2023 invoices. | F10: P1 | G10: 8 | H10: answered | I10: LM-04 / coverage is set equality with the chronology | J10: test_coverage_is_l5_as_a_set_equality_check - every chronology fact appears in coverage with an effect or an exclusion, so a date the brief gave cannot be silently unused
A11: B-10 | B11: code audit | C11: agents/* | D11: A prompt change lands in only one of two prompt systems | E11: The consult path uses _CONSULT_PROMPT; the structured-intake path builds its own _narrow_prompt and never touches it. A change described as global applies to half the product. | F11: P1 | G11: 5 | H11: answered | I11: F-11 / a prompt has exactly one owner | J11: test_a_prompt_has_exactly_one_owner - no prompt string appears in two modules, so a change cannot land in half the product. The legacy split between _CONSULT_PROMPT and intake_engine._narrow_prompt is unchanged and stays that way
A12: B-11 | B12: code audit | C12: agents/orchestrator | D12: Andhra Pradesh authority is weighted without regard to date | E12: _court_weight gives AP a flat rung, so a 2015 AP judgment (binding on Telangana as the predecessor court) and a 2022 one (another state's HC, persuasive only) are treated identically. The year is already in the record. | F12: P2 | G12: 3 | H12: answered | I12: V-04 / binding computed from court, year and forum | J12: nm/knowledge/authority.py - a citation carries binding or persuasive RELATIVE to the forum asking, and the year is part of the computation rather than a tiebreak
A13: B-12 | B13: code audit | C13: agents/orchestrator | D13: A court-ranking rung matches nothing | E13: The `telangana` rung in _court_weight is dead code, because the corpus holds no Telangana judgments at all. | F13: P3 | G13: 1 | H13: open | I13: I-03 (ingest Telangana HC) | J13: 0 Telangana HC judgments in 33,791
... A141: B-140 | B141: Phase 8 second review | C141: nm/tests/a_logic/test_served_api.py | D141: Nothing asserted that a held-back disagreement ever ARRIVES | E141: Found by mutation rather than by review: stopping the disagreements being joined to the draft left the suite green. Held back and then dropped is worse than not held back at all - AB-21's whole value is the difficult thing being said, and it would have gone silently. Both halves are now asserted on the wire: the improper fix cannot leave early, and the doubt does arrive after the screen. | F141: P1 | G141: 1 | H141: fixed | I141: AB-21 / D16.21 | J141: test_a_disagreement_reaches_the_advocate_after_the_screen
A142: B-141 | B142: Phase 8 second review | C142: nm/core/duty.py::Breach | D142: The duty taxonomy has no explicit confidentiality, privilege or conflict outcome | E142: The seven Breach values cover litigation misconduct and say nothing explicit about a recommendation that would breach confidentiality or privilege, or that acts in a conflict. The conflict CHECK is a different control on a different object - it screens the matter, not the advice - so a recommendation that itself creates the problem is unscreened. Recorded rather than fixed: adding categories to a closed list is the easy half, and the hard half is the over-application bound for each, which needs the same both-directions measurement the existing seven had. | F142: P2 | G142: 1 | H142: open | I142: AB-01 / D16.1
A143: B-142 | B143: Phase 8 second review | C143: nm/app/consult.py::DECLARED | D143: Declared competence is a hardcoded constant, not a corpus manifest | E143: Telangana, Union of India and English are declared in the composition root and nothing checks them against what the corpus actually holds. It cannot express a court, a subject, a date range or partial coverage, so with I-03 parked the declaration is broader than the corpus behind it - which makes the competence screen answer confidently about matters it has thin coverage for. Already recorded as this tenet's main gap; restated here as a defect because a declaration nothing verifies is the same class as a rating nobody computes. | F143: P2 | G143: 1 | H143: open | I143: AB-02 / D16.2
A144: B-143 | B144: self-review before claiming AB-03 | C144: nm/app/state.py::Conversations.all | D144: One unreadable matter took the conflict screen down for the whole deployment | E144: Found by attacking my own code rather than by review. The registry is a projection of the stored matters, so a row that will not decode - a partial write, a restore, a rotated key - raised out of all() and every matter on the deployment became unscreenable. The OBVIOUS repair is to skip it, and that is worse than the crash: a matter silently dropped from the registry is a FALSE CLEARANCE, the one outcome this screen exists to prevent. Fixed with a MatterSet that carries the matters and the failures together, so a caller cannot iterate one without seeing the other, and the screening note says the screen was INCOMPLETE and names what it could not cover. | F144: P1 | G144: 1 | H144: fixed | I144: AB-03 / D16.3 | J144: test_one_unreadable_matter_does_not_take_the_screen_down
A145: B-144 | B145: self-review before claiming AB-03 | C145: nm/app/conflicts.py::screening_note | D145: The screening note counted the matter against itself | E145: The registry is a projection and by the time the board renders, THIS matter is one of the stored ones - so the note said 'screened against 1 matter' on the very first brief a deployment ever saw, which is precisely the false reassurance the note exists to prevent. screen() already excludes self; the count now agrees with it. | F145: P2 | G145: 1 | H145: fixed | I145: AB-03 / D16.3 | J145: test_a_shared_party_blocks_the_second_matter_over_http
A146: B-145 | B146: self-review before claiming AB-06 | C146: nm/app/consult.py | D146: An emergency found on one turn vanished on the next | E146: The triage was recomputed from each message and kept nothing, so an arrest found on turn one was gone by turn two - the same defect the competence block had, in the place where it costs most. Conversation now carries every class assessed, not just the live ones, because the question D16.6 asks is not what was found but what was LOOKED AT. | F146: P1 | G146: 1 | H146: fixed | I146: AB-06 / D16.6 | J146: test_an_emergency_found_on_one_turn_still_leads_the_next
A147: B-146 | B147: self-review before claiming AB-06 | C147: nm/core/urgency.py::carry_forward | D147: A later NO silently closed a live emergency, and my first fix had this wrong | E147: The carry-forward rule said 'a class assessed this turn replaces what was held'. That is wrong for the same reason the competence bypass was wrong: THE STEP IS NEVER SILENT. Asked about 'the wall went up in January' it answers 'liberty | NO | does not arise on these facts' - truthful about that message, and it would close an arrest found the turn before. The unit tests passed; a SERVED test caught it. A live urgency is now sticky and only urgency.resolve closes it, with a name. The first sticky guard was then too broad and blocked the resolution itself - caught by the same test - so it tests STANDING rather than is_live, because a resolution is APPLIES-and-closed. | F147: P1 | G147: 1 | H147: fixed | I147: AB-06 / D16.6 | J147: test_a_later_NO_does_not_clear_a_live_urgency
A148: B-147 | B148: self-review before claiming AB-06 | C148: nm/app/triage.py::run | D148: An outage in the urgency step took the whole turn down | E148: The call raised straight out of run(), the consult died, and the advocate got an error page instead of an answer - the one behaviour every other screen in this build avoids. An empty Triage is INCOMPLETE by set equality, so it now reports itself as never having looked rather than as having found nothing, blocks_merits stays true, and the answer says so on its face. | F148: P1 | G148: 1 | H148: fixed | I148: AB-06 / D16.6 | J148: test_a_triage_outage_returns_an_incomplete_screen_rather_than_raising
A149: B-148 | B149: self-review before claiming AB-06 | C149: nm/app/consult.py::_urgent_lead | D149: An action due eight months ago was listed under 'these will not wait' | E149: Which reads as a forecast about something that has already failed to happen. An overdue emergency is worse news than a live one, not stale news: it leads separately, says how many days late it is, and is not filtered out. Same class as the expired-limitation defect, which this build had already fixed once. | F149: P1 | G149: 1 | H149: fixed | I149: AB-06 / D16.6 | J149: test_an_overdue_urgency_is_separated_from_one_still_ahead
